Workbook

Sheet MARET
A1: BUKU KAS BANTU
A2: 02 MARET 2026 | G2: SISA BULAN LL | H2: =SUM(C5) -> 175000
G3: UG AMBIL | H3: =
A4: NO | B4: NOMOR PERKARA | C4: URAIAN | D4: PENERIMAAN | E4: PENGELUARAN | F4: KET | G4: TOTAL | H4: =SUM(C5,D25,D50,D114,D146,D236,D162,D262,D274,D294,D312,D355,D374,D387) -> 1254000
A5: SALDO BULAN LALU | C5: 175000 | D5: - | E5: - | G5: PENGELUARAN | H5: =SUM(E25+E50+E114+E146+E162+E236+E262+E274+E294+E312+E355+E374+E387) -> 614500
A6: 1 | B6: 3/Pdt.P/2026/PN Ntn | C6: Panjar Biaya Perkara | D6: 100000 | G6: SISA | H6: =H4-H5 -> 639500
A7: 2 | B7: 3/Pdt.P/2026/PN Ntn | C7: Biaya Pendaftaran | E7: 30000
A8: 3 | B8: 3/Pdt.P/2026/PN Ntn | C8: Biaya ATK | E8: 50000
A9: 4 | J9: 82
A10: 5 | J10: 20
A11: 6 | J11: =SUM(J9:J10) -> 102
A12: 7
A13: 8
A14: 9
A15: 10
A16: 11
A17: 12
A18: 13
A19: 14
A20: 15
A21: 16
A22: 17
A23: 18
A25: Jumlah | D25: =SUM(D6:D23) -> 100000 | E25: =SUM(E6:E23) -> 80000 | R25: =-MARET!#REF! -> #REF!
G26: REK | H26: 201915000
B27: PANITERA | D27: KASIR | G27: PEMASUKAN | H27: =SUM(D25,D50,D114,D146,D162,D236,D262,D274,D294,D312,D355,D374,D387) -> 1079000
B28: PENGADILAN NEGERI RANAI | G28: JML | H28: =SUM(H26:H27) -> 202994000
G31: KONS | H31: 201915000 | P31: =6000000*70/100 -> 4200000
B32: HENDRIK HATORANGAN, S.H. | D32: ERA TRISNAWATI, SH. | G32: SALDO BANK | H32: =204367409 -> 204367409
D33: NIP. 19850723 201212 2 001 | G33: UANG PIHAK K3 DI BANK | H33: 0
J34: =H6-H33 -> 639500
A36: 4 MARET 2026
G37: UANG KAS LL | H37: 0
A38: NO | B38: NOMOR PERKARA | C38: URAIAN | D38: PENERIMAAN | E38: PENGELUARAN | F38: KET | G38: PENGELUARAN | H38: =SUM(H5) -> 614500
A39: 1 | B39: 4/Pdt.P/2026/PN Ntn | C39: Panjar Biaya Perkara | D39: 100000 | G39: SISA KAS | H39: =H6+H31 -> 202554500
A40: 2 | B40: 4/Pdt.P/2026/PN Ntn | C40: Biaya Pendaftaran | E40: 30000
A41: 3 | B41: 4/Pdt.P/2026/PN Ntn | C41: Biaya ATK | E41: 50000
A42: 4
A50: Jumlah | D50: =SUM(D39:D49) -> 100000 | E50: =SUM(E39:E49) -> 80000
A53: 6 MARET 2026
...

Sheet LAP MARET
A1: PENGADILAN NEGERI NATUNA KELAS II
A2: Jl. Batu Sisir - Kota Ranai Kec. Bunguran Timur Kab. Natuna
B4: LAPORAN KEUANGAN PERKARA PERDATA
B6: BULAN : MARET 2026
A8: NO | B8: U R A I A N | C8: J U M L A H | H8: saldo awal /akhir | I8: =D12 -> 175000
A9: URUT | C9: PENERIMAAN | E9: PENGELUARAN | H9: Penerimaan | I9: 100000
A10: 1 | B10: 2 | D10: 3 | F10: 4 | I10: 100000
I11: 18500
A12: 1 | B12: Sisa Awal ……………...…….…………… | C12: Rp | D12: =MARET!C5 -> 175000 | E12: Rp | F12: 0 | I12: 13000
A13: 2 | B13: Penerimaan Bulan ini …….……..…..…… | C13: Rp | D13: =SUM(MARET!H27) -> 1079000 | E13: Rp | F13: 0 | I13: 15000
A14: 3 | B14: Biaya Panggilan …………………………. | E14: Rp | F14: =REKAP!A175 -> 83000 | I14: 832500
A15: 4 | B15: Biaya Penerjemah …………..…………… | E15: Rp | F15: 0
A16: 5 | B16: Biaya Sita ……………….……….………. | E16: Rp | F16: 0
A17: 6 | B17: Biaya Pemeriksaan Setempat ………..…. | E17: Rp | F17: =REKAP!K175 -> 0 | K17: Pengeluaran | L17: =G26 -> 614500
A18: 7 | B18: Biaya Sumpah ……………………..…..… | E18: Rp | F18: 0 | L18: =L19-L17 -> 639500
A19: 8 | B19: Biaya Pemberitahuan ……….…….…….. | E19: Rp | F19: =SUM(REKAP!B175) -> 100000 | K19: Total | L19: =I23 -> 1254000
A20: 9 | B20: Pengiriman Biaya Perkara ……….….…. | E20: Rp | F20: =REKAP!G175 -> 0
A21: 10 | B21: Materai …………………………....…..…. | E21: Rp | F21: =REKAP!F175 -> 30000
A22: 11 | B22: Hak-Hak Kepaniteraan ………...….……. | E22: Rp | F22: =REKAP!C176 -> 216500 | H22: Jumlah Penerimaan | I22: =SUM(I9:I21) -> 1079000 | K22: SALDO BANK | L22: =I31 -> 201915000
A23: 12 | B23: Pengembalian Sisa Panjar Biaya Perkara | E23: Rp | F23: =REKAP!J175 -> 35000 | H23: Total | I23: =SUM(I8,I22) -> 1254000 | K23: KONSINYASI | L23: =I28 -> 201915000
A24: 13 | B24: Biaya Proses ………………………. | E24: Rp | F24: =REKAP!H175 -> 0 | L24: =L22-L23 -> 0 | M24: UANG PERKARA DI BANK
A25: 14 | B25: ATK ………………………. | E25: Rp | F25: =REKAP!I175 -> 150000
G26: =SUM(F14:F25) -> 614500
A27: 15 | B27: Sisa Akhir ( Saldo) …………..……..…. | D27: 0 | E27: Rp | F27: =D31-G26 -> 639500 | H27: perdata | I27: =F27 -> 639500
H28: konsinyasi | I28: 201915000
I29: total | J29: =SUM(I27:I28) -> 202554500
H30: uang tunai | I30: =J29-I31 -> 639500
B31: JUMLAH | C31: Rp | D31: =SUM(D12:D30) -> 1254000 | E31: Rp | F31: =SUM(F14:F30) -> 1254000 | H31: saldo bank | I31: =201915000+100000-100000 -> 201915000
J32: =SUM(I30:I31) -> 202554500
B35: MENGETAHUI : | C35: RANAI, 31 MARET 2026
B36: Plt. PANITERA MUDA PERDATA | C36: KASIR
B41: HADRY B, S.H. | C41: CANIA KIRANA, A.Md.

Sheet REKAP
A2: PANGGILAN | B2: PEMBERITAHUAN | C2: HAK-HAK KEPANITERAAN | F2: MATERAI | G2: BIAYA PENGIRIMAN (BANDING, KASASI, PK) | H2: BIAYA PEMBERKASAN DAN PENJILIDAN BERKAS UPAYA HUKUM | I2: ATK | J2: PENGEMBALIAN SISA PANJAR | K2: PEMERIKSAAN SETEMPAT | L2: TOTAL PENGELUARAN | M2: MASUK | Q2: KONS pidana
C3: PENDAFTARAN | D3: REDAKSI | E3: PNBP LAIN-LAIN | M3: TK I (PERMOHONAN, GUGATAN, BANTAHAN, GUGATAN SEDERHANA, GUGATAN PERLAWANAN) | N3: BANDING | O3: KASASI | P3: PK | Q3: MASUK | R3: KELUAR
L4: =SUM(A4:K4) -> 0
M5: 100000 | S5: 3 MARET 2026 | T5: 3/Pdt.P/2026/PN Ntn
C6: 30000 | S6: 3 MARET 2026 | T6: 3/Pdt.P/2026/PN Ntn
I7: 50000 | S7: 3 MARET 2026 | T7: 3/Pdt.P/2026/PN Ntn
M8: 100000 | S8: 4 MARET 2026 | T8: 4/Pdt.P/2026/PN Ntn
C9: 30000 | S9: 4 MARET 2026 | T9: 4/Pdt.P/2026/PN Ntn
I10: 50000 | S10: 4 MARET 2026 | T10: 4/Pdt.P/2026/PN Ntn
F11: 10000 | S11: 6 MARET 2026 | T11: 2/Pdt.G/2026/PN Ntn
D12: 10000 | S12: 6 MARET 2026 | T12: 2/Pdt.G/2026/PN Ntn
E13: 10000 | S13: 6 MARET 2026 | T13: 2/Pdt.G/2026/PN Ntn
B14: 100000 | S14: 6 MARET 2026 | T14: 2/Pdt.G/2026/PN Ntn
E15: 10000 | S15: 6 MARET 2026 | T15: 2/Pdt.G/2026/PN Ntn
M16: 18500 | S16: 9 MARET 2026 | T16: 2/Pdt.G/2026/PN Ntn
E17: 18500 | S17: 9 MARET 2026 | T17: 2/Pdt.G/2026/PN Ntn
J18: 35000 | S18: 9 MARET 2026 | T18: 2/Pdt.G/2026/PN Ntn
D19: 10000 | S19: 10 MARET 2026 | T19: 3/Pdt.P/2026/PN Ntn
F20: 10000 | S20: 10 MARET 2026 | T20: 3/Pdt.P/2026/PN Ntn
M21: 13000 | S21: 11 MARET 2026 | T21: 3/Pdt.P/2026/PN Ntn
E22: 13000 | S22: 11 MARET 2026 | T22: 3/Pdt.P/2026/PN Ntn
D23: 10000 | S23: 13 MARET 2026 | T23: 4/Pdt.P/2026/PN Ntn
F24: 10000 | S24: 13 MARET 2026 | T24: 4/Pdt.P/2026/PN Ntn
M25: 15000 | S25: 16 MARET 2026 | T25: 4/Pdt.P/2026/PN Ntn
E26: 15000 | S26: 16 MARET 2026 | T26: 4/Pdt.P/2026/PN Ntn
M27: 832500 | S27: 30 MARET 2026 | T27: 3/Pdt.G/2026/PN Ntn
C28: 30000 | S28: 30 MARET 2026 | T28: 3/Pdt.G/2026/PN Ntn
I29: 50000 | S29: 30 MARET 2026 | T29: 3/Pdt.G/2026/PN Ntn
E30: 10000 | S30: 31 MARET 2026 | T30: 3/Pdt.G/2026/PN Ntn
A31: 18000 | S31: 31 MARET 2026 | T31: 3/Pdt.G/2026/PN Ntn
E32: 10000 | S32: 31 MARET 2026 | T32: 3/Pdt.G/2026/PN Ntn
A33: 65000 | S33: 31 MARET 2026 | T33: 3/Pdt.G/2026/PN Ntn
E34: 10000 | S34: 31 MARET 2026 | T34: 3/Pdt.G/2026/PN Ntn
L95: =SUM(A95:K95) -> 0
L96: =SUM(A96:K96) -> 0
L97: =SUM(A97:K97) -> 0
L98: =SUM(A98:K98) -> 0
L99: =SUM(A99:K99) -> 0
L100: =SUM(A100:K100) -> 0
L101: =SUM(A101:K101) -> 0
...

Sheet EKS
A1: PENERIMAAN | B1: MATERAI | C1: LEGES | D1: SITA EKS | E1: UPAH JS | F1: PENGUMUMAN LLG | G1: UPAH JR LLG | H1: BIAYA LLG | I1: SAKSI | J1: PBT | K1: KEAMANAN | L1: SS PANJAR | M1: PNBP | N1: BLL
A15: =SUM(A2:A7) -> 0 | B15: =SUM(B2:B7) -> 0 | C15: =SUM(C2:C7) -> 0 | D15: =SUM(D2:D7) -> 0 | E15: =SUM(E2:E7) -> 0 | F15: =SUM(F2:F7) -> 0 | G15: =SUM(G2:G7) -> 0 | H15: =SUM(H2:H7) -> 0 | ... N15: =SUM(N2:N7) -> 0
D18: MASUK | E18: =SUM(A15) -> 0
D19: KELUAR | E19: =SUM(B15:N15) -> 0

Sheet KONSINYATIE
A1: PENERIMAAN | B1: PDF | C1: PENAWARAN | D1: ATK | E1: REDAKSI | F1: MATERAI | G1: LEGES | H1: PGMBLN UANG KONS
A9: =SUM(A2:A8) -> 0 | B9: =SUM(B2:B8) -> 0 | C9: =SUM(C2:C8) -> 0 | D9: =SUM(D2:D8) -> 0 | E9: =SUM(E2:E8) -> 0 | F9: =SUM(F2:F8) -> 0 | G9: =SUM(G2:G8) -> 0 | H9: =SUM(H2:H8) -> 0 | I9: =SUM(I2:I8) -> 0
D12: MASUK | E12: =SUM(A9) -> 0
D13: KELUAR | E13: =SUM(B9:I9) -> 0

Sheet Sheet1
B4: RINCIAN BIAYA PERKARA NOMOR 1/Pdt.Sus-Parpol/2023/PN Ran
I5: 1 | J5: 100000
B6: 1. | C6: Biaya Pendaftaran | E6: : | F6: 30000 | I6: 2 | J6: 100000 | M6: 249000 | N6: =M6*5 -> 1245000
B7: 2. | C7: ATK | E7: : | F7: 50000 | I7: 3 | J7: 100000 | M7: 23000 | N7: =M7*5 -> 115000
B8: 3. | C8: Biaya Panggilan | E8: : | F8: 2186000 | I8: 4 | J8: 200000 | M8: 49500 | N8: =M8*5 -> 247500
B9: 4. | C9: PNBP | E9: : | F9: 50000 | G9: =SUM(F6:F9) -> 2316000 | I9: 5 | J9: 50000 | M9: 75000 | N9: =M9*5 -> 375000
B10: 5. | C10: Redaksi | E10: : | F10: 10000 | I10: 6 | J10: 50000
B11: 6. | C11: Materai | E11: : | F11: 10000 | G11: + | I11: 7 | J11: 50000 | N11: 375000 | P11: 75000
C12: Jumlah | F12: =SUM(F6:F11) -> 2336000 | I12: 8 | J12: 100000 | N12: 1607500 | P12: 321500
I13: 9 | J13: 100000 | N13: 1607500 | P13: 321500
I14: 10 | J14: 50000 | N14: 375000 | P14: 75000
D15: sisa | F15: 944000 | I15: 11 | J15: 50000 | N15: 375000 | P15: 75000
D16: Redaksi | F16: 10000 | I16: 12 | J16: 250000 | N16: 375000 | P16: 75000
D17: Materai | F17: 10000 | I17: 13 | J17: 100000 | N17: 1607500 | P17: 321500
F18: =SUM(F15-F16-F17) -> 924000 | G18: pengembalian sisa panjar | I18: 14 | J18: 100000 | N18: 375000 | P18: 75000
I19: 15 | J19: 50000 | N19: 80000 | P19: 80000
I20: 16 | J20: 50000 | N20: =SUM(N11:N19) -> 6777500 | P20: =SUM(P11:P19) -> 1419500
I21: 17 | J21: 50000
C22: 6/Pdt.G/2022/PN Ran | I22: 18 | J22: 30000 | P22: =N20+P20 -> 8197000
F23: 30000 | I23: 19 | J23: 30000
F24: 50000 | I24: 20 | J24: 30000
F25: 70000 | I25: 21 | J25: 30000
F26: 10000 | I26: 22 | J26: 50000
F27: 3081500 | J27: =SUM(J5:J26) -> 1720000
F28: 750000
F29: 10000 | G29: =SUM(F23:F28) -> 3991500
F30: 10000
F31: =SUM(F23:F30) -> 4011500

Sheet Sheet2
B1: BANDING | C1: 6/PDT.G/2022/PN RAN
C2: PANJAR PERKARA BANDING P1 | D2: 2360000
C3: PANJAR PERKARA BANDING P2 | D3: 2360000
D4: =SUM(D2:D3) -> 4720000
C7: PENDAFTARAN BANDING P1 | D7: 50000
C8: PENDAFTARAN BANDING P2 | D8: 50000
C9: PEMBERKASAN / ATK | D9: 50000
C10: PNBP | D10: 320000
C11: BIAYA PEMBERITAHUAN | D11: 1637000
C12: PENGIRIMAN BIAYA BANDING | D12: 150000
C13: PENGIRIMAN BERKAS PERKARA | D13: 228000
D14: =SUM(D5:D13) -> 2485000 | E14: SISA | F14: =D4-D14 -> 2235000

Sheet Sheet3
D3: keluar | E3: bayar
D5: 555000
D6: 300000
D7: 228000
D8: 2754200
E9: 1460000
D10: 1500000
D11: 300000
D12: 1600000
E13: 1765460
E14: 1971000
E15: 1000000
D16: 1053270
D18: =SUM(D5:D17) -> 8290470 | E18: =SUM(E5:E17) -> 6196460
E20: =D18-E18 -> 2094010
